Workbook

Sheet INFO
A1: Fecha envio dra | B1: Documento | C1: Paciente | D1: CONCATENAR | E1: Fecha de Inicio | F1: Fecha de Fin | G1: Total de Días | H1: Dias | I1: EPS | J1: Observacion | K1: DX | L1: FECHA | M1: ORDEN | N1: PRORROGA | O1: Tipo Incapacidad | P1: Grupo Servicio

Sheet PLANTILLAS
B3: EPS SURAMERICANA S.A. 800088702
B4: PRESCRIPCIÓN DE INCAPACIDAD/LICENCIA DE MATERNIDAD
B5: Fecha | C5: =INFO!L2 -> 0 | E5: IPS Atiende | F5: SALUDSURA BOGOTA 81007832
B6: Afiliado | C6: =INFO!D2 -> 0 | E6: EPS Afiliado | F6: =INFO!I2 -> 0
B7: Diagnóstico Principal | C7: =INFO!K2 -> 0 | E7: Diagnóstico Relacionado
B8: Causa Servicio | C8: ENF GENERAL | D8: Origen | F8: Común | G8: Prórroga | H8: =INFO!N2 -> 0
B9: Fecha Inicio | C9: =INFO!E2 -> 0 | D9: Duración | E9: =INFO!G2 -> 0 | G9: Fecha Fin | H9: =INFO!F2 -> 0
B10: Tipo Generación | C10: TRANSCRIPCION | E10: Nro. Prescripción a Sustituir | G10: =INFO!M2 -> 0
B11: Modalidad Prestación | D11: Intramural | E11: Incapacidad retroactiva | G11: NO
B12: Tipo Incapacidad | D12: =INFO!O2 -> 0 | E12: Grupo Servicio | G12: =INFO!P2 -> 0
B13: INFORMACIÓN DEL PROFESIONAL
B14: Profesional Responsable | C14: Karen Marcela Cervantes Moreno
B16: Registro Médico | C16: 52536967
B17: Institución que Expide | C17: CC- 99999 SURAMERICANA POLIZAS | G17: Reps | H17: 110010778209
B18: Afiliado: | C18: SURA
B19: Empleador o Trabajador Independiente | C19: SURAMERICANA SEGUROS.
B34: EPS SURAMERICANA S.A. 800088702
B35: PRESCRIPCIÓN DE INCAPACIDAD/LICENCIA DE MATERNIDAD
B36: Fecha | C36: =INFO!L3 -> 0 | E36: IPS Atiende | F36: SALUDSURA BOGOTA 81007832
B37: Afiliado | C37: =INFO!D3 -> 0 | E37: EPS Afiliado | F37: =INFO!I3 -> 0
B38: Diagnóstico Principal | C38: =INFO!K3 -> 0 | E38: Diagnóstico Relacionado
B39: Causa Servicio | C39: ENF GENERAL | D39: Origen | F39: Común | G39: Prórroga | H39: =INFO!N3 -> 0
B40: Fecha Inicio | C40: =INFO!E3 -> 0 | D40: Duración | E40: =INFO!G3 -> 0 | G40: Fecha Fin | H40: =INFO!F3 -> 0
B41: Tipo Generación | C41: TRANSCRIPCION | E41: Nro. Prescripción a Sustituir | G41: =INFO!M3 -> 0
B42: Modalidad Prestación | D42: Intramural | E42: Incapacidad retroactiva | G42: NO
B43: Tipo Incapacidad | D43: =INFO!O3 -> 0 | E43: Grupo Servicio | G43: =INFO!P3 -> 0
B44: INFORMACIÓN DEL PROFESIONAL
B45: Profesional Responsable | C45: Karen Marcela Cervantes Moreno
B47: Registro Médico | C47: 52536967
B48: Institución que Expide | C48: CC- 99999 SURAMERICANA POLIZAS | G48: Reps | H48: 110010778209
B49: Afiliado: | C49: SURA
B50: Empleador o Trabajador Independiente | C50: SURAMERICANA SEGUROS.
B66: EPS SURAMERICANA S.A. 800088702
B67: PRESCRIPCIÓN DE INCAPACIDAD/LICENCIA DE MATERNIDAD
B68: Fecha | C68: =INFO!L4 -> 0 | E68: IPS Atiende | F68: SALUDSURA BOGOTA 81007832
B69: Afiliado | C69: =INFO!D4 -> 0 | E69: EPS Afiliado | F69: =INFO!I4 -> 0
B70: Diagnóstico Principal | C70: =INFO!K4 -> 0 | E70: Diagnóstico Relacionado
B71: Causa Servicio | C71: ENF GENERAL | D71: Origen | F71: Común | G71: Prórroga | H71: =INFO!N4 -> 0
B72: Fecha Inicio | C72: =INFO!E4 -> 0 | D72: Duración | E72: =INFO!G4 -> 0 | G72: Fecha Fin | H72: =INFO!F4 -> 0
B73: Tipo Generación | C73: TRANSCRIPCION | E73: Nro. Prescripción a Sustituir | G73: =INFO!M4 -> 0
...
